<?xml version="1.0"?>
<robot xmlns:xacro="http://www.ros.org/wiki/xacro" name="my_robot_arm_description">
    <link name="base_link">
    </link>
    <joint name="base_link_joint" type="fixed">
        <origin rpy="0 0 0" xyz="0 0 0"/>
        <parent link="base_link"/>
        <child link="Robot_stand"/>
    </joint>
    <link name="Robot_stand">
        <visual>
        <geometry>
            <box size="0.2 0.2 0.5"/>
        </geometry>
        </visual>
    </link>
    <!--Waist Joint-->
    <joint name="Robot_stand__Waist_Joint" type="revolute">
        <axis xyz="0 0 1"/>
        <limit effort="1000.0" lower="-3.14" upper="3.14" velocity="0.5"/>
        <origin rpy="0 0 0" xyz="0 0 0.25" />
        <parent link="Robot_stand" />
        <child link="Waist_joint" />
    </joint>

    <link name="Waist_joint">
        <visual>
            <origin rpy="0 0 0" xyz="0 0 0" />
            <geometry>
                <cylinder radius="0.1" length="0.20"/>
            </geometry>
        </visual>
    </link>
    <!--Shoulder Joint-->
    <joint name="Waist_Joint__Shoulder_Joint" type="revolute">
        <axis xyz="0 0 1"/>
        <limit effort="1000.0" lower="-3.14" upper="3.14" velocity="0.5"/>
        <origin rpy="1.57 0 0" xyz="0 0 0.20" />
        <parent link="Waist_joint" />
        <child link="Shoulder_Joint" />
    </joint>

    <link name="Shoulder_Joint">
        <visual>
            <origin rpy="0 0 0" xyz="0 0 0" />
            <geometry>
                <cylinder radius="0.1" length="0.1"/>
            </geometry>
        </visual>
    </link>
    <!--link from shoulder joint to elbow joint-->
    <joint name="Shoulder_Joint__Link01" type="fixed">
        <origin rpy="0 0 0" xyz="0 0.2 0"/>
        <parent link="Shoulder_Joint"/>
        <child link="Shoulder_Joint_Link"/>
    </joint>

    <link name="Shoulder_Joint_Link">
        <visual>
            <origin rpy="0 0 0" xyz="0 0 0" />
            <geometry>
                <box size="0.1 0.4 0.1"/>
            </geometry>
        </visual>
    </link>
    <!--Elbow Joint-->
    <joint name="Link01__Elbow_Joint" type="revolute">
        <axis xyz="0 0 1"/>
        <limit effort="1000.0" lower="-3.14" upper="3.14" velocity="0.5"/>
        <origin rpy="0 0 0" xyz="0 0.3 0" />
        <parent link="Shoulder_Joint_Link" />
        <child link="Elbow_Joint" />
    </joint>

    <link name="Elbow_Joint">
        <visual>
            <origin rpy="0 0 0" xyz="0 0 0" />
            <geometry>
                <cylinder radius="0.1" length="0.1"/>
            </geometry>
        </visual>
    </link>
</robot>